<mujoco model="mycobot">
    <option integrator="implicitfast" noslip_iterations="1"/>

    <compiler angle="radian" meshdir="meshes" autolimits="true" />

    <default>
        <joint armature="0.1" damping="1" axis="0 0 1" range="-2.8973 2.8973"/>
        <geom condim="4" contype="1" conaffinity="15" friction="0.9 0.2 0.2" solref="0.001 2" />
        <motor ctrllimited="true" />
        <equality solref="0.001 2" />
        <default class="visualgeom">
            <geom material="visualgeom" condim="1" contype="0" conaffinity="0" />
        </default>
    </default>

    <asset>
        <mesh name="link1" file="link1.stl" scale="0.001 0.001 0.001" />
        <mesh name="link2" file="link2.stl" />
        <mesh name="link3" file="link3.stl" />
        <mesh name="link4" file="link4.stl" />
        <mesh name="link5" file="link5.stl" />
        <mesh name="link6" file="link6.stl" />
        <mesh name="flange" file="flange.stl" />
        
        <mesh name="gripper_base" file="base_link2.stl" scale="0.001 0.001 0.001" />
        <mesh name="gripper_rail" file="gripper_rail_base1.stl" scale="0.001 0.001 0.001" />
        <mesh name="finger_left" file="gripper_finger_21.stl" scale="0.001 0.001 0.001" />
        <mesh name="finger_right" file="gripper_finger1.stl" scale="0.001 0.001 0.001" />

        <texture name="texplane" type="2d" builtin="checker" rgb1=".0 .0 .0" rgb2=".8 .8 .8" width="100" height="100" />
        <material name="matplane" reflectance="0." texture="texplane" texrepeat="1 1" texuniform="true" />
        <material name="visualgeom" rgba="0.5 0.9 0.2 1" />
        <material name="silver" rgba="0.7 0.7 0.7 1" />
    </asset>

    <worldbody>
        <light directional="true" diffuse="0.4 0.4 0.4" specular="0.1 0.1 0.1" pos="0 0 5.0" dir="0 0 -1" castshadow="false" />
        <light directional="true" diffuse="0.6 0.6 0.6" specular="0.2 0.2 0.2" pos="0 0 4" dir="0 0 -1" />
        <geom name="ground" type="plane" pos="0 0 0" size="100 100 0.001" quat="1 0 0 0" material="matplane" condim="3" conaffinity="15" />
        <camera name="fixed" pos="0 -3.0 0.5196343916714328" xyaxes="1 0 0 0 0 1" />
        <camera name="track" mode="trackcom" pos="0 -3.0 0.5196343916714328" xyaxes="1 0 0 0 0 1" />
        <body name="root" pos="0 0 0">
        <geom type="mesh" mesh="link1" contype="1" conaffinity="0" density="0" group="1" class="visualgeom" />
        <geom type="mesh" rgba="" mesh="link1" />
        
        <body name="link2" pos="0 0 0.13956">
            <inertial pos="0 0 0" mass="1.5" diaginertia="0.01 0.01 0.01" />
            <joint name="link2_to_link1" axis="0 0 1" range="-2.9321 2.9321" />
            <geom pos="0 0 -0.06096" quat="0.707105 0 0 -0.707108" type="mesh" mesh="link2" class="visualgeom" />
            <geom type="mesh" mesh="link2" pos="0 0 -0.06096" quat="0.707105 0 0 -0.707108" />

            <body name="link3" pos="0 0 -0.001" quat="0.499998 0.500002 0.5 -0.5">
            <inertial pos="0 0 0" mass="1.2" diaginertia="0.008 0.008 0.008" />
            <joint name="link3_to_link2" axis="0 0 1" range="-2.3561 2.3561" />
            <geom pos="0 0 0.03256" quat="0.707105 0 -0.707108 0" type="mesh" mesh="link3" class="visualgeom" />
            <geom type="mesh" mesh="link3" pos="0 0 0.03256" quat="0.707105 0 -0.707108 0" />

                <body name="link4" pos="-0.1104 0 0">
                    <inertial pos="0 0 0" mass="1" diaginertia="0.005 0.005 0.005" />
                    <joint name="link4_to_link3" axis="0 0 1" range="-2.6179 2.6179" />
                    <geom pos="0 0 0.03056" quat="0.707105 0 -0.707108 0" type="mesh" mesh="link4" class="visualgeom" />
                    <geom type="mesh" mesh="link4" pos="0 0 0.03056" quat="0.707105 0 -0.707108 0" />
                        <body name="link5" pos="-0.096 0 0.06462" quat="0.707105 0 0 -0.707108">
                        <inertial pos="0 0 0" mass="0.8" diaginertia="0.003 0.003 0.003" />
                        <joint name="link5_to_link4" axis="0 0 1" range="-2.5307 2.5307" />
                        <geom pos="0 -0.001 -0.0345" quat="0.499998 0.500002 -0.5 0.5" type="mesh" mesh="link5" class="visualgeom" />
                        <geom type="mesh" mesh="link5" pos="0 -0.001 -0.0345" quat="0.499998 0.500002 -0.5 0.5" />

                        <body name="link6" pos="0 -0.07318 -0.001" quat="0.499998 0.5 -0.5 0.500002">
                            <inertial pos="0 0 0" mass="0.5" diaginertia="0.002 0.002 0.002" />
                            <joint name="link6_to_link5" axis="0 0 1" range="-2.8797 2.8797" />
                            <geom pos="0 0 -0.038" type="mesh" mesh="link6" class="visualgeom" />
                            <geom type="mesh" mesh="link6" pos="0 0 -0.038" />

                            <body name="link6_flange" pos="0 0.0456 0" quat="0.707105 -0.707108 0 0">
                            <site name="attachment_site" pos="0 0.0 0.075" size="0.005" rgba="1 0 0 1" group="1"/>
                            <inertial pos="0.000969617 3.10966e-05 0.0070873" quat="0.997515 -0.0019461 0.0697529 -0.00976369" mass="0.3" diaginertia="0.00103948 0.00103651 0.00100478" />
                            <joint name="link6output_to_link6" axis="0 0 1" range="-3.14 3.14159" />
                            <geom pos="0 0 -0.012" type="mesh" mesh="flange" class="visualgeom" />
                            <geom type="mesh" mesh="flange" pos="0 0 -0.012" />

                            <body name="gripper_base" pos="0 0 0" quat="1 0 0 0">
                                <geom type="mesh" mesh="gripper_base" material="silver" />
                                
                                <body name="gripper_rail" pos="0 0 0" quat="1 0 0 0">
                                <geom type="mesh" mesh="gripper_rail" material="silver" />
                                
                                <body name="finger_left" pos="0 0 0">
                                    <inertial pos="0 -0.017022 0.0224353" quat="0.947802 0.318861 0 0" mass="0.03" diaginertia="0.000211896 0.000211896 0.0002" />
                                    <joint name="Slider_10" type="slide" axis="1 0 0" range="-0.02 0.01" />
                                    <geom type="mesh" mesh="finger_left" pos="0 0 0" material="silver" contype="0" conaffinity="0" group="1"/>
                                    <geom name="finger_left_pad" type="box" size="0.002 0.015 0.01" pos="0.022 0.0 0.07" friction="2.0 0.05 0.0001" solref="0.02 1" contype="2" conaffinity="5" rgba="0.3 0.3 0.3 1" />
                                </body>

                                <body name="finger_right" pos="0 0 0">
                                    <inertial pos="0 0.01688 0.022582" quat="0.948936 -0.315467 0 0" mass="0.03" diaginertia="0.000211923 0.000211923 0.0002" />
                                    <joint name="Slider_11" type="slide" axis="1 0 0" range="-0.01 0.02" />
                                    <geom type="mesh" mesh="finger_right" pos="0 0 0" material="silver" contype="0" conaffinity="0" group="1"/>
                                    <geom name="finger_right_pad" type="box" size="0.002 0.015 0.01" pos="-0.022 0.0 0.07" friction="2.0 0.05 0.0001" solref="0.02 1" contype="2" conaffinity="5" rgba="0.3 0.3 0.3 1" />
                                </body>
                                </body>
                            </body>
                            </body>
                        </body>
                        </body>
                    </body>
                    </body>
                </body>
                </body>
    </worldbody>

  <actuator>
    <position name="link2_to_link1" joint="link2_to_link1" ctrllimited="true" ctrlrange="-2.9321 2.9321" kp="500" kv="50" />
    <position name="link3_to_link2" joint="link3_to_link2" ctrllimited="true" ctrlrange="-2.3561 2.3561" kp="500" kv="50" />
    <position name="link4_to_link3" joint="link4_to_link3" ctrllimited="true" ctrlrange="-2.6179 2.6179" kp="400" kv="40" />
    <position name="link5_to_link4" joint="link5_to_link4" ctrllimited="true" ctrlrange="-2.5307 2.5307" kp="300" kv="30" />
    <position name="link6_to_link5" joint="link6_to_link5" ctrllimited="true" ctrlrange="-2.8797 2.8797" kp="200" kv="20" />
    <position name="link6output_to_link6" joint="link6output_to_link6" ctrllimited="true" ctrlrange="-3.1416 3.1416" kp="10" />
    <position name="gripper_l" joint="Slider_10" ctrlrange="-0.02 0.02" kp="100" kv="20" />
    <position name="gripper_r" joint="Slider_11" ctrlrange="-0.02 0.02" kp="100" kv="20" />
  </actuator>

  <contact>
    <exclude body1="root" body2="link2"/>
    <exclude body1="link2" body2="link3"/>
    <exclude body1="link3" body2="link4"/>
    <exclude body1="link4" body2="link5"/>
    <exclude body1="link5" body2="link6"/>
    <exclude body1="link6_flange" body2="gripper_base"/>
    <exclude body1="gripper_base" body2="gripper_rail"/>
    <exclude body1="finger_left" body2="finger_right"/>
    <exclude body1="gripper_base" body2="finger_left"/>
    <exclude body1="gripper_base" body2="finger_right"/>
    <exclude body1="gripper_rail" body2="finger_left"/>
    <exclude body1="gripper_rail" body2="finger_right"/>
  </contact>
</mujoco>